2021-08-05 09:59:13 kuan_table.py[line:309] ERROR 无法获取数据,错误db:api_loansuper_x2,user_id:1015814,
报错原因:
Traceback (most recent call last):
  File "/opt/model_servers/model_wuboyuan/kuan_data/kuan_table.py", line 317, in get_app_connect_feat
    return data_1_i[app_connect_feat].iloc[0].to_json()
  File "/usr/local/python3/lib/python3.6/site-packages/pandas/core/frame.py", line 3001, in __getitem__
    indexer = self.loc._convert_to_indexer(key, axis=1, raise_missing=True)
  File "/usr/local/python3/lib/python3.6/site-packages/pandas/core/indexing.py", line 1285, in _convert_to_indexer
    return self._get_listlike_indexer(obj, axis, **kwargs)[1]
  File "/usr/local/python3/lib/python3.6/site-packages/pandas/core/indexing.py", line 1092, in _get_listlike_indexer
    keyarr, indexer, o._get_axis_number(axis), raise_missing=raise_missing
  File "/usr/local/python3/lib/python3.6/site-packages/pandas/core/indexing.py", line 1185, in _validate_read_indexer
    raise KeyError("{} not in index".format(not_found))
KeyError: "['7install_to_create_daysothers'] not in index"

2021-08-05 09:59:13 _internal.py[line:225] INFO 47.57.242.55 - - [05/Aug/2021 09:59:13] "GET /kuan_table_J_x2/loan_id/1015814 HTTP/1.1" 200 -
2021-08-05 10:17:41 kuan_table.py[line:309] ERROR 无法获取数据,错误db:api_loansuper_x3,user_id:1015814,
报错原因:
Traceback (most recent call last):
  File "/opt/model_servers/model_wuboyuan/kuan_data/kuan_table.py", line 313, in get_app_connect_feat
    data_1_i=kuan_table(db=db,loan_id=loan_id).iloc[-1:]
  File "/opt/model_servers/model_wuboyuan/kuan_data/kuan_table.py", line 285, in kuan_table
    app_data=pd.DataFrame(eval(get_requests(data_applist['applist_json'].iloc[0], encod=True)))
  File "/usr/local/python3/lib/python3.6/site-packages/pandas/core/indexing.py", line 1424, in __getitem__
    return self._getitem_axis(maybe_callable, axis=axis)
  File "/usr/local/python3/lib/python3.6/site-packages/pandas/core/indexing.py", line 2157, in _getitem_axis
    self._validate_integer(key, axis)
  File "/usr/local/python3/lib/python3.6/site-packages/pandas/core/indexing.py", line 2088, in _validate_integer
    raise IndexError("single positional indexer is out-of-bounds")
IndexError: single positional indexer is out-of-bounds

2021-08-05 10:17:41 _internal.py[line:225] INFO 47.57.242.55 - - [05/Aug/2021 10:17:41] "GET /kuan_table_J_x3/loan_id/1015814 HTTP/1.1" 200 -
2021-08-05 10:26:27 kuan_table.py[line:309] ERROR 无法获取数据,错误db:api_loansuper,user_id:1031570,
报错原因:
Traceback (most recent call last):
  File "/opt/model_servers/model_wuboyuan/kuan_data/kuan_table.py", line 313, in get_app_connect_feat
    data_1_i=kuan_table(db=db,loan_id=loan_id).iloc[-1:]
  File "/opt/model_servers/model_wuboyuan/kuan_data/kuan_table.py", line 293, in kuan_table
    add_phone_feat_data=add_phone_feat(db=db,loan_id=loan_id)
  File "/opt/model_servers/model_wuboyuan/kuan_data/kuan_table.py", line 253, in add_phone_feat
    data_phone=get_conncet(db=db,loan_id=loan_id).iloc[-1:]
  File "/opt/model_servers/model_wuboyuan/kuan_data/kuan_table.py", line 247, in get_conncet
    df = pd.read_sql(sql2, conn)
  File "/usr/local/python3/lib/python3.6/site-packages/pandas/io/sql.py", line 410, in read_sql
    chunksize=chunksize,
  File "/usr/local/python3/lib/python3.6/site-packages/pandas/io/sql.py", line 1645, in read_query
    cursor = self.execute(*args)
  File "/usr/local/python3/lib/python3.6/site-packages/pandas/io/sql.py", line 1595, in execute
    cur.execute(*args)
  File "/usr/local/python3/lib/python3.6/site-packages/pymysql/cursors.py", line 170, in execute
    result = self._query(query)
  File "/usr/local/python3/lib/python3.6/site-packages/pymysql/cursors.py", line 328, in _query
    conn.query(q)
  File "/usr/local/python3/lib/python3.6/site-packages/pymysql/connections.py", line 517, in query
    self._affected_rows = self._read_query_result(unbuffered=unbuffered)
  File "/usr/local/python3/lib/python3.6/site-packages/pymysql/connections.py", line 732, in _read_query_result
    result.read()
  File "/usr/local/python3/lib/python3.6/site-packages/pymysql/connections.py", line 1075, in read
    first_packet = self.connection._read_packet()
  File "/usr/local/python3/lib/python3.6/site-packages/pymysql/connections.py", line 657, in _read_packet
    packet_header = self._read_bytes(4)
  File "/usr/local/python3/lib/python3.6/site-packages/pymysql/connections.py", line 691, in _read_bytes
    data = self._rfile.read(num_bytes)
  File "/usr/local/python3/lib/python3.6/socket.py", line 586, in readinto
    return self._sock.recv_into(b)
  File "/usr/local/python3/lib/python3.6/site-packages/gunicorn/workers/base.py", line 203, in handle_abort
    sys.exit(1)
SystemExit: 1

2021-08-05 10:28:28 kuan_table.py[line:309] ERROR 无法获取数据,错误db:api_loansuper_x2,user_id:1015814,
报错原因:
Traceback (most recent call last):
  File "/opt/model_servers/model_wuboyuan/kuan_data/kuan_table.py", line 317, in get_app_connect_feat
    return data_1_i[app_connect_feat].iloc[0].to_json()
  File "/usr/local/python3/lib/python3.6/site-packages/pandas/core/frame.py", line 3001, in __getitem__
    indexer = self.loc._convert_to_indexer(key, axis=1, raise_missing=True)
  File "/usr/local/python3/lib/python3.6/site-packages/pandas/core/indexing.py", line 1285, in _convert_to_indexer
    return self._get_listlike_indexer(obj, axis, **kwargs)[1]
  File "/usr/local/python3/lib/python3.6/site-packages/pandas/core/indexing.py", line 1092, in _get_listlike_indexer
    keyarr, indexer, o._get_axis_number(axis), raise_missing=raise_missing
  File "/usr/local/python3/lib/python3.6/site-packages/pandas/core/indexing.py", line 1185, in _validate_read_indexer
    raise KeyError("{} not in index".format(not_found))
KeyError: "['7install_to_create_daysothers'] not in index"

2021-08-05 10:28:34 kuan_table.py[line:309] ERROR 无法获取数据,错误db:api_loansuper_x3,user_id:1015814,
报错原因:
Traceback (most recent call last):
  File "/opt/model_servers/model_wuboyuan/kuan_data/kuan_table.py", line 313, in get_app_connect_feat
    data_1_i=kuan_table(db=db,loan_id=loan_id).iloc[-1:]
  File "/opt/model_servers/model_wuboyuan/kuan_data/kuan_table.py", line 285, in kuan_table
    app_data=pd.DataFrame(eval(get_requests(data_applist['applist_json'].iloc[0], encod=True)))
  File "/usr/local/python3/lib/python3.6/site-packages/pandas/core/indexing.py", line 1424, in __getitem__
    return self._getitem_axis(maybe_callable, axis=axis)
  File "/usr/local/python3/lib/python3.6/site-packages/pandas/core/indexing.py", line 2157, in _getitem_axis
    self._validate_integer(key, axis)
  File "/usr/local/python3/lib/python3.6/site-packages/pandas/core/indexing.py", line 2088, in _validate_integer
    raise IndexError("single positional indexer is out-of-bounds")
IndexError: single positional indexer is out-of-bounds

2021-08-05 10:29:06 kuan_table.py[line:309] ERROR 无法获取数据,错误db:api_loansuper_x4,user_id:961926,
报错原因:
Traceback (most recent call last):
  File "/opt/model_servers/model_wuboyuan/kuan_data/kuan_table.py", line 313, in get_app_connect_feat
    data_1_i=kuan_table(db=db,loan_id=loan_id).iloc[-1:]
  File "/opt/model_servers/model_wuboyuan/kuan_data/kuan_table.py", line 293, in kuan_table
    add_phone_feat_data=add_phone_feat(db=db,loan_id=loan_id)
  File "/opt/model_servers/model_wuboyuan/kuan_data/kuan_table.py", line 253, in add_phone_feat
    data_phone=get_conncet(db=db,loan_id=loan_id).iloc[-1:]
  File "/opt/model_servers/model_wuboyuan/kuan_data/kuan_table.py", line 247, in get_conncet
    df = pd.read_sql(sql2, conn)
  File "/usr/local/python3/lib/python3.6/site-packages/pandas/io/sql.py", line 410, in read_sql
    chunksize=chunksize,
  File "/usr/local/python3/lib/python3.6/site-packages/pandas/io/sql.py", line 1645, in read_query
    cursor = self.execute(*args)
  File "/usr/local/python3/lib/python3.6/site-packages/pandas/io/sql.py", line 1595, in execute
    cur.execute(*args)
  File "/usr/local/python3/lib/python3.6/site-packages/pymysql/cursors.py", line 170, in execute
    result = self._query(query)
  File "/usr/local/python3/lib/python3.6/site-packages/pymysql/cursors.py", line 328, in _query
    conn.query(q)
  File "/usr/local/python3/lib/python3.6/site-packages/pymysql/connections.py", line 517, in query
    self._affected_rows = self._read_query_result(unbuffered=unbuffered)
  File "/usr/local/python3/lib/python3.6/site-packages/pymysql/connections.py", line 732, in _read_query_result
    result.read()
  File "/usr/local/python3/lib/python3.6/site-packages/pymysql/connections.py", line 1075, in read
    first_packet = self.connection._read_packet()
  File "/usr/local/python3/lib/python3.6/site-packages/pymysql/connections.py", line 657, in _read_packet
    packet_header = self._read_bytes(4)
  File "/usr/local/python3/lib/python3.6/site-packages/pymysql/connections.py", line 691, in _read_bytes
    data = self._rfile.read(num_bytes)
  File "/usr/local/python3/lib/python3.6/socket.py", line 586, in readinto
    return self._sock.recv_into(b)
  File "/usr/local/python3/lib/python3.6/site-packages/gunicorn/workers/base.py", line 203, in handle_abort
    sys.exit(1)
SystemExit: 1

2021-08-05 10:29:14 kuan_table.py[line:309] ERROR 无法获取数据,错误db:api_loansuper_x5,user_id:998904,
报错原因:
Traceback (most recent call last):
  File "/opt/model_servers/model_wuboyuan/kuan_data/kuan_table.py", line 313, in get_app_connect_feat
    data_1_i=kuan_table(db=db,loan_id=loan_id).iloc[-1:]
  File "/opt/model_servers/model_wuboyuan/kuan_data/kuan_table.py", line 293, in kuan_table
    add_phone_feat_data=add_phone_feat(db=db,loan_id=loan_id)
  File "/opt/model_servers/model_wuboyuan/kuan_data/kuan_table.py", line 253, in add_phone_feat
    data_phone=get_conncet(db=db,loan_id=loan_id).iloc[-1:]
  File "/opt/model_servers/model_wuboyuan/kuan_data/kuan_table.py", line 247, in get_conncet
    df = pd.read_sql(sql2, conn)
  File "/usr/local/python3/lib/python3.6/site-packages/pandas/io/sql.py", line 410, in read_sql
    chunksize=chunksize,
  File "/usr/local/python3/lib/python3.6/site-packages/pandas/io/sql.py", line 1645, in read_query
    cursor = self.execute(*args)
  File "/usr/local/python3/lib/python3.6/site-packages/pandas/io/sql.py", line 1595, in execute
    cur.execute(*args)
  File "/usr/local/python3/lib/python3.6/site-packages/pymysql/cursors.py", line 170, in execute
    result = self._query(query)
  File "/usr/local/python3/lib/python3.6/site-packages/pymysql/cursors.py", line 328, in _query
    conn.query(q)
  File "/usr/local/python3/lib/python3.6/site-packages/pymysql/connections.py", line 517, in query
    self._affected_rows = self._read_query_result(unbuffered=unbuffered)
  File "/usr/local/python3/lib/python3.6/site-packages/pymysql/connections.py", line 732, in _read_query_result
    result.read()
  File "/usr/local/python3/lib/python3.6/site-packages/pymysql/connections.py", line 1075, in read
    first_packet = self.connection._read_packet()
  File "/usr/local/python3/lib/python3.6/site-packages/pymysql/connections.py", line 657, in _read_packet
    packet_header = self._read_bytes(4)
  File "/usr/local/python3/lib/python3.6/site-packages/pymysql/connections.py", line 691, in _read_bytes
    data = self._rfile.read(num_bytes)
  File "/usr/local/python3/lib/python3.6/socket.py", line 586, in readinto
    return self._sock.recv_into(b)
  File "/usr/local/python3/lib/python3.6/site-packages/gunicorn/workers/base.py", line 203, in handle_abort
    sys.exit(1)
SystemExit: 1

